<mujoco model="GR2T2v2">
  <compiler inertiafromgeom='auto' angle='radian' eulerseq='zyx' meshdir='../meshes/'/>
  <size nuser_actuator='1' nuser_sensor='1' nuser_geom='1'/>
  <option timestep='0.001' iterations='100' tolerance="1e-8" solver="Newton" integrator="RK4" gravity='0 0 -9.81'>
     <flag contact="enable" energy="enable"/>
  </option>

  <default>
    <!-- <default class="joint_1">
      <joint limited="true" damping="1.0" armature="0.1" frictionloss="0.5" />
    </default> -->

    <default class="joint_1">
      <joint limited="true" />
    </default>

    <default class="visual">
      <geom type="mesh" contype="0" conaffinity="0" rgba="0.752941 0.752941 0.752941 1"/>
    </default>
    
    <default class="collision">
      <geom mass="0" rgba="0 0 0 0"/>
    </default>

    <geom contype="0" conaffinity="0" condim="1" solref="0.005 1"/>
    <equality solref="0.005 1"/>

  </default>

  <asset>
    <texture type='skybox' builtin='gradient' width='128' height='128' rgb1='0.4 0.6 0.8' rgb2='0 0 0'/>
    <texture name='plane' type='2d' builtin='checker' rgb1='0.2 0.2 0.2' rgb2='0.3 0.3 0.3' width='512' height='512'/>
    <material name='plane' reflectance='0.0' texture='plane' texrepeat='1 1' texuniform='true'/>
    <material name='collision' rgba='0.1 0.5 0.9 0'/>
    <material name='obstacle'  rgba='0.2 0.6 0.2 1'/>
    <hfield name="hfield" file="hfield.png" size="10 10 .05 0.1"/>
    <hfield name="hill" file="cos-lines.png" size="10 10 0.08 0.1"/>

    <texture name="body" type="cube" builtin="flat" mark="cross" width="128" height="128" rgb1="0.8 0.6 0.4" rgb2="0.8 0.6 0.4" markrgb="1 1 1"/>
    <material name="body" texture="body" texuniform="true" rgba="0.8 0.6 .4 1"/>
    <texture name="grid" type="2d" builtin="checker" width="512" height="512" rgb1=".1 .2 .3" rgb2=".2 .3 .4"/>
    <material name="grid" texture="grid" texrepeat="1 1" texuniform="true" reflectance=".2"/>

    <mesh name="base_link" file="base_link.STL"/>
    <mesh name="waist_yaw_link" file="waist_yaw_link.STL"/>
    <mesh name="torso_link" file="torso_link.STL"/>
    <mesh name="head_yaw_link" file="head_yaw_link.STL"/>
    <mesh name="head_pitch_link" file="head_pitch_link.STL"/>
    <mesh name="left_upper_arm_pitch_link" file="left_upper_arm_pitch_link.STL"/>
    <mesh name="left_upper_arm_roll_link" file="left_upper_arm_roll_link.STL"/>
    <mesh name="left_upper_arm_yaw_link" file="left_upper_arm_yaw_link.STL"/>
    <mesh name="left_lower_arm_pitch_link" file="left_lower_arm_pitch_link.STL"/>
    <mesh name="left_hand_yaw_link" file="left_hand_yaw_link.STL"/>
    <mesh name="left_hand_pitch_link" file="left_hand_pitch_link.STL"/>
    <mesh name="left_hand_roll_link" file="left_hand_roll_link.STL"/>
    <mesh name="right_upper_arm_pitch_link" file="right_upper_arm_pitch_link.STL"/>
    <mesh name="right_upper_arm_roll_link" file="right_upper_arm_roll_link.STL"/>
    <mesh name="right_upper_arm_yaw_link" file="right_upper_arm_yaw_link.STL"/>
    <mesh name="right_lower_arm_pitch_link" file="right_lower_arm_pitch_link.STL"/>
    <mesh name="right_hand_yaw_link" file="right_hand_yaw_link.STL"/>
    <mesh name="right_hand_pitch_link" file="right_hand_pitch_link.STL"/>
    <mesh name="right_hand_roll_link" file="right_hand_roll_link.STL"/>
    <mesh name="left_thigh_pitch_link" file="left_thigh_pitch_link.STL"/>
    <mesh name="left_thigh_roll_link" file="left_thigh_roll_link.STL"/>
    <mesh name="left_thigh_yaw_link" file="left_thigh_yaw_link.STL"/>
    <mesh name="left_shank_pitch_link" file="left_shank_pitch_link.STL"/>
    <mesh name="left_foot_pitch_link" file="left_foot_pitch_link.STL"/>
    <mesh name="left_foot_roll_link" file="left_foot_roll_link.STL"/>
    <mesh name="right_thigh_pitch_link" file="right_thigh_pitch_link.STL"/>
    <mesh name="right_thigh_roll_link" file="right_thigh_roll_link.STL"/>
    <mesh name="right_thigh_yaw_link" file="right_thigh_yaw_link.STL"/>
    <mesh name="right_shank_pitch_link" file="right_shank_pitch_link.STL"/>
    <mesh name="right_foot_pitch_link" file="right_foot_pitch_link.STL"/>
    <mesh name="right_foot_roll_link" file="right_foot_roll_link.STL"/>
  </asset>
  <worldbody>
    <geom name='floor' pos='0.001 0 0' size='100 10 .125' type='plane' material='plane' condim='3' contype="15" conaffinity='15'/>
    <light mode='trackcom' pos='0 0 5' dir='0 0 -1'/>
    <light directional='true' pos='0 0 3' dir='0 0 -1' diffuse='0.2 0.2 0.2' specular='0 0 0'/>

    <body name="base_link" pos='0 0 0.99'>
      <inertial pos="-0.0030357 6.968E-05 -0.087284" quat="1 0.0 0.0 0.0" mass="6.6598" diaginertia="0.048356 0.030781 0.041191" />
      <freejoint name="float_base" />
      <camera name="track1" pos="1.958 -2.348 0.591" xyaxes="0.768 0.641 0.000 -0.101 0.122 0.987" mode="trackcom"/>
      <camera name="back" pos="-4.5 0 1" xyaxes="0 -1 0 1 0 3" mode="trackcom"/>
      <geom class='visual' mesh="base_link" />
      <site name='imu' size='0.01' pos='-0.059 0 -0.068'/>

      <body name="left_thigh_pitch_link" pos="0 0.076867 -0.12355" quat="0.965926 -0.25882 0 0">
        <inertial pos="-0.035065 0.036467 0.0020083" quat="0.148217 0.621705 -0.336914 0.691378" mass="2.61" diaginertia="0.0117524 0.0112934 0.00485715"/>
        <joint name="left_hip_pitch_joint" pos="0 0 0" axis="0 1 0" range="-2.618 2.618" class='joint_1' armature='0.592'/>
        <geom  class='visual'  mesh="left_thigh_pitch_link"/>
        <body name="left_thigh_roll_link" pos="-0.062 0.0729 0" quat="0.965926 0.25882 0 0">
          <inertial pos="0.027776 -0.00010848 -0.0074687" quat="-0.00754734 0.775274 -0.0068887 0.631542" mass="1.3487" diaginertia="0.00283572 0.00263683 0.00111045"/>
          <joint name="left_hip_roll_joint" pos="0 0 0" axis="1 0 0" range="-0.59341 1.5708" class='joint_1' armature='0.121'/>
          <geom  class='visual'  mesh="left_thigh_roll_link"/>
          <!-- <geom size="0.05 0.09" pos="0.025 0 0" quat="0.707388 0 0.706825 0" type="cylinder" rgba="1 1 1 1"/> -->
          <body name="left_thigh_yaw_link" pos="0.062 0 -0.03495">
            <inertial pos="0.0010147 -0.012758 -0.14387" quat="0.678148 0.00564457 -0.015008 0.73475" mass="5.1152" diaginertia="0.0432183 0.0422948 0.00988572"/>
            <joint name="left_hip_yaw_joint" pos="0 0 0" axis="0 0 1" range="-0.69813 1.5708" class='joint_1' armature='0.165'/>
            <geom  class='visual'  mesh="left_thigh_yaw_link"/>
            <!-- <geom size="0.06 0.13" pos="0 0 -0.19" type="cylinder" rgba="1 1 1 1"/> -->
            <body name="left_shank_pitch_link" pos="0 0 -0.34305">
              <inertial pos="0.004743 -0.0014414 -0.1756" quat="0.692529 0.0125941 -0.0117144 0.721185" mass="3.5932" diaginertia="0.0354035 0.0348803 0.00428939"/>
              <joint name="left_knee_pitch_joint" pos="0 0 0" axis="0 1 0" range="-0.087266 2.3562" class='joint_1' armature='0.121'/>
              <geom  class='visual'  mesh="left_shank_pitch_link"/>
              <!-- <geom size="0.05 0.09" pos="0 0 -0.165" type="cylinder" rgba="1 1 1 1"/> -->
              <body name="left_foot_pitch_link" pos="0 0 -0.406">
                <inertial pos="0.026267 1.226e-05 0.0010987" quat="-0.0560581 0.713517 -0.0571676 0.696049" mass="0.17877" diaginertia="0.000220267 0.000219111 1.24827e-05"/>
                <joint name="left_ankle_pitch_joint" pos="0 0 0" axis="0 1 0" range="-0.7854 0.7854" class='joint_1' armature='0.165'/>
                <geom  class='visual'  mesh="left_foot_pitch_link"/>
                <body name="left_foot_roll_link">
                  <inertial pos="0.050086 0.006159 -0.032795" quat="-0.0752306 0.721459 -0.127307 0.676484" mass="1.1232" diaginertia="0.00729384 0.00667953 0.00120783"/>
                  <joint name="left_ankle_roll_joint" pos="0 0 0" axis="1 0 0" range="-0.38397 0.38397" class='joint_1' armature='0.031'/>
                  <!-- <geom class='visual' mesh="left_foot_roll_link"/>
                  <geom type="mesh" mesh="left_foot_roll_link" contype="1" conaffinity="1" group="1"/> -->
                  <!-- <geom contype="1" conaffinity="1" group="1" density="0" size="0.025 0.14" pos="0.06 -0.025 -0.033" quat="0.707388 0 0.706825 0" type="cylinder" rgba="1 1 1 1"/>
                  <geom contype="1" conaffinity="1" group="1" density="0" size="0.025 0.14" pos="0.06 0.025 -0.033" quat="0.707388 0 0.706825 0" type="cylinder" rgba="1 1 1 1"/> -->
                  <geom type="box" contype="1" conaffinity="1" group="1" pos="0.06 0 -0.048" size="0.14 0.05 0.01 "  solref="0.005 1"/>
                </body>
              </body>
            </body>
          </body>
        </body>
      </body>
      <body name="right_thigh_pitch_link" pos="0 -0.076867 -0.12355" quat="0.965926 0.25882 0 0">
        <inertial pos="-0.035065 -0.036467 0.0020083" quat="-0.148217 0.621705 0.336914 0.691378" mass="2.61" diaginertia="0.0117524 0.0112934 0.00485715"/>
        <joint name="right_hip_pitch_joint" pos="0 0 0" axis="0 1 0" range="-2.618 2.618" class='joint_1' armature='0.592'/>
        <geom  class='visual'  mesh="right_thigh_pitch_link"/>
        <body name="right_thigh_roll_link" pos="-0.062 -0.0729 0" quat="0.965926 -0.25882 0 0">
          <inertial pos="0.027776 0.00010848 -0.0074687" quat="0.00754734 0.775274 0.0068887 0.631542" mass="1.3487" diaginertia="0.00283572 0.00263683 0.00111045"/>
          <joint name="right_hip_roll_joint" pos="0 0 0" axis="1 0 0" range="-1.5708 0.59341" class='joint_1' armature='0.121'/>
          <geom  class='visual'  mesh="right_thigh_roll_link"/>
          <!-- <geom size="0.05 0.09" pos="0.025 0 0" quat="0.707388 0 0.706825 0" type="cylinder" rgba="1 1 1 1"/> -->
          <body name="right_thigh_yaw_link" pos="0.062 0 -0.03495">
            <inertial pos="0.0010147 0.012758 -0.14387" quat="0.73475 -0.015008 0.00564457 0.678148" mass="5.1152" diaginertia="0.0432183 0.0422948 0.00988572"/>
            <joint name="right_hip_yaw_joint" pos="0 0 0" axis="0 0 1" range="-1.5708 0.69813" class='joint_1' armature='0.165'/>
            <geom  class='visual'  mesh="right_thigh_yaw_link"/>
            <!-- <geom size="0.06 0.13" pos="0 0 -0.19" type="cylinder" rgba="1 1 1 1"/> -->
            <body name="right_shank_pitch_link" pos="0 0 -0.34305">
              <inertial pos="0.004743 0.0014414 -0.1756" quat="0.721185 -0.0117144 0.0125941 0.692529" mass="3.5932" diaginertia="0.0354035 0.0348803 0.00428939"/>
              <joint name="right_knee_pitch_joint" pos="0 0 0" axis="0 1 0" range="-0.087266 2.3562" class='joint_1' armature='0.121'/>
              <geom  class='visual'  mesh="right_shank_pitch_link"/>
              <!-- <geom size="0.05 0.09" pos="0 0 -0.165" type="cylinder" rgba="1 1 1 1"/> -->
              <body name="right_foot_pitch_link" pos="0 0 -0.406">
                <inertial pos="0.026267 -1.226e-05 0.0010987" quat="0.0560581 0.713517 0.0571676 0.696049" mass="0.17877" diaginertia="0.000220267 0.000219111 1.24827e-05"/>
                <joint name="right_ankle_pitch_joint" pos="0 0 0" axis="0 1 0" range="-0.7854 0.7854" class='joint_1' armature='0.165'/>
                <geom  class='visual'  mesh="right_foot_pitch_link"/>
                <body name="right_foot_roll_link">
                  <inertial pos="0.050086 -0.006159 -0.032795" quat="0.0752306 0.721459 0.127307 0.676484" mass="1.1232" diaginertia="0.00729384 0.00667953 0.00120783"/>
                  <joint name="right_ankle_roll_joint" pos="0 0 0" axis="1 0 0" range="-0.38397 0.38397" class='joint_1' armature='0.031'/>
                  <!-- <geom class='visual' mesh="right_foot_roll_link"/>
                  <geom type="mesh" mesh="right_foot_roll_link" contype="1" conaffinity="1" group="1"/> -->
                  <!-- <geom contype="1" conaffinity="1" group="1" density="0" size="0.025 0.14" pos="0.06 -0.025 -0.033" quat="0.707388 0 0.706825 0" type="cylinder" rgba="1 1 1 1"/>
                  <geom contype="1" conaffinity="1" group="1" density="0" size="0.025 0.14" pos="0.06 0.025 -0.033" quat="0.707388 0 0.706825 0" type="cylinder" rgba="1 1 1 1"/> -->
                  <geom type="box" contype="1" conaffinity="1" group="1"  pos="0.06 0 -0.048" size="0.14 0.05 0.01 "  solref="0.005 1"/>
                </body>
              </body>
            </body>
          </body>
        </body>
      </body>

      <body name="waist_yaw_link" pos="0 0 -0.0159">
        <inertial pos="-0.00517481 0.00101795 0.262162" quat="0.999991 0.000675722 0.00389605 0.00147319" mass="14.7305" diaginertia="0.29551 0.256667 0.111299"/>
        <joint name="waist_yaw_joint" pos="0 0 0" axis="0 0 1" range="-2.618 2.618" class='joint_1' armature='0.606'/>
        <geom  class='visual'  mesh="waist_yaw_link"/>
        <geom pos="0 0 0.39681"  class='visual'  mesh="torso_link"/>
        <!-- <geom size="0.15 0.15" pos="0 0 0.26681" type="cylinder" rgba="1 1 1 1"/> -->
        <body name="head_yaw_link" pos="0.001 0 0.50742">
          <inertial pos="0 0.0099543 0.0065646" quat="0.972635 -0.232338 0 0" mass="0.1402" diaginertia="0.00012944 0.000126981 2.79892e-05"/>
          <!-- <joint name="head_yaw_joint" pos="0 0 0" axis="0 0 1" range="-1.3963 1.3963"/> -->
          <geom  class='visual'  mesh="head_yaw_link"/>
          <body name="head_pitch_link" pos="0 0 0.044185">
            <inertial pos="0.031582 0.0012059 0.072239" quat="0.694215 0.113508 0.0964382 0.704188" mass="1.6096" diaginertia="0.0104269 0.00789733 0.00590535"/>
            <!-- <joint name="head_pitch_joint" pos="0 0 0" axis="0 1 0" range="-0.5236 0.5236"/> -->
            <geom  class='visual'  mesh="head_pitch_link"/>
            <!-- <geom size="0.09" pos="0.02 0 0.07" rgba="1 1 1 1"/> -->
          </body>
        </body>
        <body name="left_upper_arm_pitch_link" pos="0 0.15115 0.39681">
          <inertial pos="0.0022312 0.040265 3.797e-05" quat="0.706989 0.706971 -0.0130037 -0.0137803" mass="1.3432" diaginertia="0.00318387 0.0030442 0.00125333"/>
          <joint name="left_shoulder_pitch_joint" pos="0 0 0" axis="0 1 0" range="-2.9671 2.9671" class='joint_1' armature='0.606'/>
          <geom  class='visual'  mesh="left_upper_arm_pitch_link"/>
          <body name="left_upper_arm_roll_link" pos="0 0.078848 0">
            <inertial pos="0.0087432 0.0022878 -0.038787" quat="0.731821 0.0644488 0.0680057 0.675026" mass="0.96142" diaginertia="0.00280254 0.00267381 0.000848354"/>
            <joint name="left_shoulder_roll_joint" pos="0 0 0" axis="1 0 0" range="-0.5236 2.7925" class='joint_1' armature='0.606'/>
            <geom  class='visual'  mesh="left_upper_arm_roll_link"/>
            <geom size="0.045" rgba="1 1 1 1"/>
            <body name="left_upper_arm_yaw_link" pos="0 0 -0.09438">
              <inertial pos="-0.00056161 0.0012137 -0.091108" quat="0.711973 0.00606212 -0.00534792 0.70216" mass="1.3181" diaginertia="0.00680739 0.0067903 0.0010838"/>
              <joint name="left_shoulder_yaw_joint" pos="0 0 0" axis="0 0 1" range="-1.8326 1.8326" class='joint_1' armature='0.222'/>
              <geom  class='visual'  mesh="left_upper_arm_yaw_link"/>
              <!-- <geom size="0.04 0.05" pos="0 0 -0.05" type="cylinder" rgba="1 1 1 1"/> -->
              <body name="left_lower_arm_pitch_link" pos="0 0 -0.16111" quat="0.980795 0 -0.195042 0">
                <inertial pos="-0.0014862 0.006973 -0.021097" quat="0.988022 -0.153585 0.00398239 -0.014411" mass="0.45807" diaginertia="0.000689859 0.000595495 0.000367996"/>
                <joint name="left_elbow_pitch_joint" pos="0 0 0" axis="0 1 0" range="-1.5272 0.47997" class='joint_1' armature='0.222'/>
                <geom  class='visual'  mesh="left_lower_arm_pitch_link"/>
                <body name="left_hand_yaw_link" pos="0 0 -0.058525">
                  <inertial pos="0.00027991 0.0038031 -0.062955" quat="0.998141 0.0514847 -0.00557981 -0.0321454" mass="1.0855" diaginertia="0.00236057 0.00224794 0.00087367"/>
                  <!-- <joint name="left_wrist_yaw_joint" pos="0 0 0" axis="0 0 1" range="-1.8326 1.8326"/> -->
                  <geom  class='visual'  mesh="left_hand_yaw_link"/>
                  <!-- <geom size="0.045 0.0575" pos="0 0 -0.05" type="cylinder" rgba="1 1 1 1"/> -->
                  <body name="left_hand_pitch_link" pos="0 0 -0.16102">
                    <inertial pos="0.0038604 2.7474e-05 2.9411e-06" quat="-0.0260138 0.704893 0.00415181 0.708824" mass="0.45716" diaginertia="0.000234837 0.000228139 0.000219414"/>
                    <!-- <joint name="left_wrist_pitch_joint" pos="0 0 0" axis="0 1 0" range="-0.61087 0.61087"/> -->
                    <geom  class='visual'  mesh="left_hand_pitch_link"/>
                    <body name="left_hand_roll_link">
                      <inertial pos="0.0087325 -2.8386e-05 -0.015719" quat="0.605545 0.36526 0.366039 0.60491" mass="0.20259" diaginertia="0.00019338 0.000159959 0.000100541"/>
                      <!-- <joint name="left_wrist_roll_joint" pos="0 0 0" axis="1 0 0" range="-0.95993 0.95993"/> -->
                      <geom  class='visual'  mesh="left_hand_roll_link"/>
                    </body>
                  </body>
                </body>
              </body>
            </body>
          </body>
        </body>
        <body name="right_upper_arm_pitch_link" pos="0 -0.1585 0.39681">
          <inertial pos="0.0022312 -0.040265 3.797e-05" quat="0.706971 0.706989 0.0137803 0.0130037" mass="1.3432" diaginertia="0.00318387 0.0030442 0.00125333"/>
          <joint name="right_shoulder_pitch_joint" pos="0 0 0" axis="0 1 0" range="-2.9671 2.9671" class='joint_1' armature='0.606'/>
          <geom  class='visual'  mesh="right_upper_arm_pitch_link"/>
          <body name="right_upper_arm_roll_link" pos="0 -0.071498 0">
            <inertial pos="0.0087432 -0.0022878 -0.038787" quat="0.675026 0.0680057 0.0644488 0.731821" mass="0.96142" diaginertia="0.00280254 0.00267381 0.000848354"/>
            <joint name="right_shoulder_roll_joint" pos="0 0 0" axis="1 0 0" range="-2.7925 0.5236" class='joint_1' armature='0.606'/>
            <geom  class='visual'  mesh="right_upper_arm_roll_link"/>
            <geom size="0.045" rgba="1 1 1 1"/>
            <body name="right_upper_arm_yaw_link" pos="0 0 -0.09438">
              <inertial pos="-0.00056161 -0.0012137 -0.091108" quat="0.70216 -0.00534792 0.00606212 0.711973" mass="1.3181" diaginertia="0.00680739 0.0067903 0.0010838"/>
              <joint name="right_shoulder_yaw_joint" pos="0 0 0" axis="0 0 1" range="-1.8326 1.8326" class='joint_1' armature='0.222'/>
              <geom  class='visual'  mesh="right_upper_arm_yaw_link"/>
              <!-- <geom size="0.04 0.05" pos="0 0 -0.05" type="cylinder" rgba="1 1 1 1"/> -->
              <body name="right_lower_arm_pitch_link" pos="0 0 -0.16111" quat="0.98079 0 -0.195066 0">
                <inertial pos="-0.0014862 -0.006973 -0.021097" quat="0.988022 0.153585 0.00398239 0.014411" mass="0.45807" diaginertia="0.000689859 0.000595495 0.000367996"/>
                <joint name="right_elbow_pitch_joint" pos="0 0 0" axis="0 1 0" range="-1.5272 0.47997" class='joint_1' armature='0.222'/>
                <geom  class='visual'  mesh="right_lower_arm_pitch_link"/>
                <body name="right_hand_yaw_link" pos="0 0 -0.058525">
                  <inertial pos="0.00027991 -0.0038031 -0.062955" quat="0.998141 -0.0514847 -0.00557981 0.0321454" mass="1.0855" diaginertia="0.00236057 0.00224794 0.00087367"/>
                  <!-- <joint name="right_wrist_yaw_joint" pos="0 0 0" axis="0 0 1" range="-1.8326 1.8326"/> -->
                  <geom  class='visual'  mesh="right_hand_yaw_link"/>
                  <!-- <geom size="0.045 0.05775" pos="0 0 -0.05" type="cylinder" rgba="1 1 1 1"/> -->
                  <body name="right_hand_pitch_link" pos="0 0 -0.16102">
                    <inertial pos="0.0038604 -2.7474e-05 2.9411e-06" quat="0.0260138 0.704893 -0.00415181 0.708824" mass="0.45716" diaginertia="0.000234837 0.000228139 0.000219414"/>
                    <!-- <joint name="right_wrist_pitch_joint" pos="0 0 0" axis="0 1 0" range="-0.61087 0.61087"/> -->
                    <geom  class='visual'  mesh="right_hand_pitch_link"/>
                    <body name="right_hand_roll_link">
                      <inertial pos="0.0087325 2.8386e-05 -0.015719" quat="0.60491 0.366039 0.36526 0.605545" mass="0.20259" diaginertia="0.00019338 0.000159959 0.000100541"/>
                      <!-- <joint name="right_wrist_roll_joint" pos="0 0 0" axis="1 0 0" range="-0.95993 0.95993"/> -->
                      <geom  class='visual'  mesh="right_hand_roll_link"/>
                    </body>
                  </body>
                </body>
              </body>
            </body>
          </body>
        </body>
      </body>
    </body>

    <geom name='floor1' pos='11 0 0' size='10 10 .125' type="hfield" hfield="hfield" condim='3' contype="15" conaffinity='15' rgba="1.0000 0.9804 0.9804 1"/>
    <geom name='floor2' pos='32.0 0 0' size='10 10 .125' type='hfield' hfield='hill' condim='3' contype="15" conaffinity='15' rgba="1.0000 0.9804 0.9804 1"/>
    <!-- <geom name='box1' pos='22.1 0 0.01' size='1 10 0.05' type='box' condim='3' conaffinity='15' group='2'/>
    <geom name='box2' pos='23.1 0 0.01' size='1 10 0.1' type='box' condim='3' conaffinity='15' group='2'/>
    <geom name='box3' pos='24.1 0 0.01' size='1 10 0.15' type='box' condim='3' conaffinity='15' group='2'/>
    <geom name='box4' pos='25.1 0 0.01' size='1 10 0.20' type='box' condim='3' conaffinity='15' group='2'/>
    <geom name='box5' pos='26.1 0 0.01' size='1 10 0.25' type='box' condim='3' conaffinity='15' group='2'/>
    <geom name='box6' pos='27.1 0 0.01' size='1 10 0.30' type='box' condim='3' conaffinity='15' group='2'/>
    <geom name='box7' pos='28.1 0 0.01' size='1 10 0.35' type='box' condim='3' conaffinity='15' group='2'/>
    <geom name='box8' pos='29.1 0 0.01' size='1 10 0.40' type='box' condim='3' conaffinity='15' group='2'/>
    <geom name='box9' pos='30.1 0 0.01' size='1 10 0.45' type='box' condim='3' conaffinity='15' group='2'/>
    <geom name='box10' pos='31.1 0 0.01' size='1 10 0.5' type='box' condim='3' conaffinity='15' group='2'/>
    <geom name='box11' pos='32.1 0 0.01' size='1 10 0.55' type='box' condim='3' conaffinity='15' group='2'/>
    <geom name='box12' pos='33.1 0 0.01' size='1 10 0.6' type='box' condim='3' conaffinity='15' group='2'/>
    <geom name='box13' pos='34.1 0 0.01' size='1 10 0.65' type='box' condim='3' conaffinity='15' group='2'/>
    <geom name='box14' pos='35.1 0 0.01' size='1 10 0.7' type='box' condim='3' conaffinity='15' group='2'/>
    <geom name='box15' pos='36.1 0 0.01' size='1 10 0.75' type='box' condim='3' conaffinity='15' group='2'/> -->
<!-- 
    <geom name='box1' pos='12.1 0 0.01' size='1 10 0.1' type='box' condim='3' conaffinity='15' group='2'/>
    <geom name='box2' pos='13.1 0 0.01' size='1 10 0.2' type='box' condim='3' conaffinity='15' group='2'/>
    <geom name='box3' pos='14.1 0 0.01' size='1 10 0.3' type='box' condim='3' conaffinity='15' group='2'/>
    <geom name='box4' pos='15.1 0 0.01' size='1 10 0.4' type='box' condim='3' conaffinity='15' group='2'/>
    <geom name='box5' pos='16.1 0 0.01' size='1 10 0.5' type='box' condim='3' conaffinity='15' group='2'/>
    <geom name='box6' pos='17.1 0 0.01' size='1 10 0.6' type='box' condim='3' conaffinity='15' group='2'/>
    <geom name='box7' pos='18.1 0 0.01' size='1 10 0.7' type='box' condim='3' conaffinity='15' group='2'/>
    <geom name='box8' pos='19.1 0 0.01' size='1 10 0.8' type='box' condim='3' conaffinity='15' group='2'/>
    <geom name='box9' pos='20.1 0 0.01' size='1 10 0.9' type='box' condim='3' conaffinity='15' group='2'/>
    <geom name='box10' pos='21.1 0 0.01' size='1 10 1.0' type='box' condim='3' conaffinity='15' group='2'/>
    <geom name='box11' pos='22.1 0 0.01' size='1 10 1.1' type='box' condim='3' conaffinity='15' group='2'/>
    <geom name='box12' pos='23.1 0 0.01' size='1 10 1.2' type='box' condim='3' conaffinity='15' group='2'/>
    <geom name='box13' pos='24.1 0 0.01' size='1 10 1.3' type='box' condim='3' conaffinity='15' group='2'/>
    <geom name='box14' pos='25.1 0 0.01' size='1 10 1.4' type='box' condim='3' conaffinity='15' group='2'/>
    <geom name='box15' pos='26.1 0 0.01' size='1 10 1.5' type='box' condim='3' conaffinity='15' group='2'/> -->

    <geom name='box1' pos='12.1 0 0.01' size='4.5 10 0.1' type='box' condim='3' conaffinity='15' group='2'/>
    <geom name='box2' pos='12.1 0 0.01' size='4 10 0.2' type='box' condim='3' conaffinity='15' group='2'/>
    <geom name='box3' pos='12.1 0 0.01' size='3.5 10 0.3' type='box' condim='3' conaffinity='15' group='2'/>
    <geom name='box4' pos='12.1 0 0.01' size='3 10 0.4' type='box' condim='3' conaffinity='15' group='2'/>
    <geom name='box5' pos='12.1 0 0.01' size='2.5 10 0.5' type='box' condim='3' conaffinity='15' group='2'/>
    <geom name='box6' pos='12.1 0 0.01' size='2 10 0.6' type='box' condim='3' conaffinity='15' group='2'/>
    <geom name='box7' pos='12.1 0 0.01' size='1.5 10 0.7' type='box' condim='3' conaffinity='15' group='2'/>
    <geom name='box8' pos='12.1 0 0.01' size='1 10 0.8' type='box' condim='3' conaffinity='15' group='2'/>
    <geom name='box9' pos='12.1 0 0.01' size='0.5 10 0.9' type='box' condim='3' conaffinity='15' group='2'/>
    <geom name='box10' pos='20.1 0 0.01' size='4.5 10 0.1' euler='0 -0.174 0' type='box' condim='3' conaffinity='15' group='2'/>
    <geom name='box11' pos='26.5 0 0.80' size='2 10 0.1' euler='0 0 0' type='box' condim='3' conaffinity='15' group='2'/>
    <geom name='box12' pos='32.5 0 0.01' size='4.5 10 0.1' euler='0 0.174 0' type='box' condim='3' conaffinity='15' group='2'/>

    <!-- <geom name='floor2' pos='20.1 0 0' size='5 10 .125' euler='0 -0.174 0' type='plane' material='plane1' condim='3' contype="15" conaffinity='15' solref="0.005 1"/> -->

    <!-- stairs -->
      <!-- <geom name='box1' pos='2.1 0 0.01' size='1 10 0.1' type='box' condim='3' conaffinity='15' group='2'/>
      <geom name='box2' pos='3.1 0 0.01' size='1 10 0.2' type='box' condim='3' conaffinity='15' group='2'/>
      <geom name='box3' pos='4.1 0 0.01' size='1 10 0.3' type='box' condim='3' conaffinity='15' group='2'/>
      <geom name='box4' pos='5.1 0 0.01' size='1 10 0.4' type='box' condim='3' conaffinity='15' group='2'/>
      <geom name='box5' pos='6.1 0 0.01' size='1 10 0.5' type='box' condim='3' conaffinity='15' group='2'/>
      <geom name='box6' pos='7.1 0 0.01' size='1 10 0.6' type='box' condim='3' conaffinity='15' group='2'/>
      <geom name='box7' pos='8.1 0 0.01' size='1 10 0.7' type='box' condim='3' conaffinity='15' group='2'/>
      <geom name='box8' pos='9.1 0 0.01' size='1 10 0.8' type='box' condim='3' conaffinity='15' group='2'/>
      <geom name='box9' pos='10.1 0 0.01' size='1 10 0.9' type='box' condim='3' conaffinity='15' group='2'/>
      <geom name='box10' pos='11.1 0 0.01' size='1 10 1.0' type='box' condim='3' conaffinity='15' group='2'/>
      <geom name='box11' pos='12.1 0 0.01' size='1 10 1.1' type='box' condim='3' conaffinity='15' group='2'/>
      <geom name='box12' pos='13.1 0 0.01' size='1 10 1.2' type='box' condim='3' conaffinity='15' group='2'/>
      <geom name='box13' pos='14.1 0 0.01' size='1 10 1.3' type='box' condim='3' conaffinity='15' group='2'/>
      <geom name='box14' pos='15.1 0 0.01' size='1 10 1.4' type='box' condim='3' conaffinity='15' group='2'/>
      <geom name='box15' pos='16.1 0 0.01' size='1 10 1.5' type='box' condim='3' conaffinity='15' group='2'/> -->

      <!-- <geom name='box1' pos='2.1 0 0.01' size='1 10 0.05' type='box' condim='3' conaffinity='15' group='2'/>
      <geom name='box2' pos='3.1 0 0.01' size='1 10 0.1' type='box' condim='3' conaffinity='15' group='2'/>
      <geom name='box3' pos='4.1 0 0.01' size='1 10 0.15' type='box' condim='3' conaffinity='15' group='2'/>
      <geom name='box4' pos='5.1 0 0.01' size='1 10 0.20' type='box' condim='3' conaffinity='15' group='2'/>
      <geom name='box5' pos='6.1 0 0.01' size='1 10 0.25' type='box' condim='3' conaffinity='15' group='2'/>
      <geom name='box6' pos='7.1 0 0.01' size='1 10 0.30' type='box' condim='3' conaffinity='15' group='2'/>
      <geom name='box7' pos='8.1 0 0.01' size='1 10 0.35' type='box' condim='3' conaffinity='15' group='2'/>
      <geom name='box8' pos='9.1 0 0.01' size='1 10 0.40' type='box' condim='3' conaffinity='15' group='2'/>
      <geom name='box9' pos='10.1 0 0.01' size='1 10 0.45' type='box' condim='3' conaffinity='15' group='2'/>
      <geom name='box10' pos='11.1 0 0.01' size='1 10 0.5' type='box' condim='3' conaffinity='15' group='2'/>
      <geom name='box11' pos='12.1 0 0.01' size='1 10 0.55' type='box' condim='3' conaffinity='15' group='2'/>
      <geom name='box12' pos='13.1 0 0.01' size='1 10 0.6' type='box' condim='3' conaffinity='15' group='2'/>
      <geom name='box13' pos='14.1 0 0.01' size='1 10 0.65' type='box' condim='3' conaffinity='15' group='2'/>
      <geom name='box14' pos='15.1 0 0.01' size='1 10 0.7' type='box' condim='3' conaffinity='15' group='2'/>
      <geom name='box15' pos='16.1 0 0.01' size='1 10 0.75' type='box' condim='3' conaffinity='15' group='2'/> -->

       <!-- <geom name='box1' pos='2.1 20 0.01' size='1 1 0.1' type='box' condim='3' conaffinity='15' group='2'/>
      <geom name='box2' pos='3.1 20 0.01' size='1 1 0.2' type='box' condim='3' conaffinity='15' group='2'/>
      <geom name='box3' pos='4.1 20 0.01' size='1 1 0.3' type='box' condim='3' conaffinity='15' group='2'/>
      <geom name='box4' pos='5.1 20 0.01' size='1 1 0.4' type='box' condim='3' conaffinity='15' group='2'/>
      <geom name='box5' pos='6.1 20 0.01' size='1 1 0.5' type='box' condim='3' conaffinity='15' group='2'/>
      <geom name='box6' pos='7.1 20 0.01' size='1 1 0.6' type='box' condim='3' conaffinity='15' group='2'/>
      <geom name='box7' pos='8.1 20 0.01' size='1 1 0.7' type='box' condim='3' conaffinity='15' group='2'/>
      <geom name='box8' pos='9.1 20 0.01' size='1 1 0.8' type='box' condim='3' conaffinity='15' group='2'/>
      <geom name='box9' pos='10.1 20 0.01' size='1 1 0.9' type='box' condim='3' conaffinity='15' group='2'/>
      <geom name='box10' pos='11.1 20 0.01' size='1 1 1.0' type='box' condim='3' conaffinity='15' group='2'/>
      <geom name='box11' pos='12.1 20 0.01' size='1 1 1.1' type='box' condim='3' conaffinity='15' group='2'/>
      <geom name='box12' pos='13.1 20 0.01' size='1 1 1.2' type='box' condim='3' conaffinity='15' group='2'/>
      <geom name='box13' pos='14.1 20 0.01' size='1 1 1.3' type='box' condim='3' conaffinity='15' group='2'/>
      <geom name='box14' pos='15.1 20 0.01' size='1 1 1.4' type='box' condim='3' conaffinity='15' group='2'/>
      <geom name='box15' pos='16.1 20 0.01' size='1 1 1.5' type='box' condim='3' conaffinity='15' group='2'/> -->
  </worldbody>

  <!-- Actuators (Force control) -->
  <actuator>
    <!-- <motor name="waist_yaw_joint" joint="waist_yaw_joint" gear='1' /> -->
    <!-- Left Leg Actuators -->
    <motor name="left_hip_pitch_joint" joint='left_hip_pitch_joint' gear='1' ctrllimited="true" ctrlrange="-366.05 366.05"/>
    <motor name="left_hip_roll_joint" joint="left_hip_roll_joint" gear='1' ctrllimited="true" ctrlrange="-95.472 95.472"/>
    <motor name="left_hip_yaw_joint" joint='left_hip_yaw_joint' gear='1' ctrllimited="true" ctrlrange="-54.33 54.33"/>
    <motor name="left_knee_pitch_joint" joint='left_knee_pitch_joint' gear='1' ctrllimited="true" ctrlrange="-366.05 366.05"/>
    <motor name="left_ankle_pitch_joint" joint='left_ankle_pitch_joint' gear='1' ctrllimited="true" ctrlrange="-54.33 54.33"/>
    <motor name="left_ankle_roll_joint" joint='left_ankle_roll_joint' gear='1' ctrllimited="true" ctrlrange="-29.835 29.835"/>

    <!-- Right Leg Actuators -->
    <motor name="right_hip_pitch_joint" joint="right_hip_pitch_joint" gear='1' ctrllimited="true" ctrlrange="-366.05 366.05"/>
    <motor name="right_hip_roll_joint" joint="right_hip_roll_joint" gear='1' ctrllimited="true" ctrlrange="-95.472 95.472"/>
    <motor name="right_hip_yaw_joint" joint="right_hip_yaw_joint" gear='1' ctrllimited="true" ctrlrange="-54.33 54.33"/>
    <motor name="right_knee_pitch_joint" joint="right_knee_pitch_joint" gear='1' ctrllimited="true" ctrlrange="-366.05 366.05"/>
    <motor name="right_ankle_pitch_joint" joint="right_ankle_pitch_joint" gear='1' ctrllimited="true" ctrlrange="-54.33 54.33"/>
    <motor name="right_ankle_roll_joint" joint="right_ankle_roll_joint" gear='1' ctrllimited="true" ctrlrange="-29.835 29.835"/>

    <!-- Waist Actuators -->
    <motor name="waist_yaw_joint" joint="waist_yaw_joint" gear='1' ctrllimited="true" ctrlrange="-74.45 74.45"/>

    <!-- Head Actuators -->
    <!-- <motor name="head_yaw_joint" joint="head_yaw_joint" gear='1' />
    <motor name="head_pitch_joint" joint="head_pitch_joint" gear='1' /> -->
    

    <!-- Left Arm Actuators -->
    <motor name="left_shoulder_pitch_joint" joint="left_shoulder_pitch_joint" gear='1' ctrllimited="true" ctrlrange="-74.45 74.45"/>
    <motor name="left_shoulder_roll_joint" joint="left_shoulder_roll_joint" gear='1' ctrllimited="true" ctrlrange="-74.45 74.45"/>
    <motor name="left_shoulder_yaw_joint" joint="left_shoulder_yaw_joint" gear='1' ctrllimited="true" ctrlrange="-42.75 42.75"/>
    <motor name="left_elbow_pitch_joint" joint="left_elbow_pitch_joint" gear='1' ctrllimited="true" ctrlrange="-42.75 42.75"/>
    <!-- <motor name="left_wrist_yaw_joint" joint="left_wrist_yaw_joint" gear='1' ctrllimited="true" ctrlrange="-30 30"/>
    <motor name="left_wrist_pitch_joint" joint="left_wrist_pitch_joint" gear='1' ctrllimited="true" ctrlrange="-30 30"/>
    <motor name="left_wrist_roll_joint" joint="left_wrist_roll_joint" gear='1' ctrllimited="true" ctrlrange="-30 30"/> -->

    <!-- Right Arm Actuators -->
    <motor name="right_shoulder_pitch_joint" joint="right_shoulder_pitch_joint" gear='1' ctrllimited="true" ctrlrange="-74.45 74.45"/>
    <motor name="right_shoulder_roll_joint" joint="right_shoulder_roll_joint" gear='1' ctrllimited="true" ctrlrange="-74.45 74.45"/>
    <motor name="right_shoulder_yaw_joint" joint="right_shoulder_yaw_joint" gear='1' ctrllimited="true" ctrlrange="-42.75 42.75"/>
    <motor name="right_elbow_pitch_joint" joint="right_elbow_pitch_joint" gear='1' ctrllimited="true" ctrlrange="-42.75 42.75"/>
    <!-- <motor name="right_wrist_yaw_joint" joint="right_wrist_yaw_joint" gear='1' ctrllimited="true" ctrlrange="-30 30"/>
    <motor name="right_wrist_pitch_joint" joint="right_wrist_pitch_joint" gear='1' ctrllimited="true" ctrlrange="-30 30"/>
    <motor name="right_wrist_roll_joint" joint="right_wrist_roll_joint" gear='1' ctrllimited="true" ctrlrange="-30 30"/> -->



  </actuator>

  <sensor>
    <!-- IMU Sensor -->
    <!-- <framequat name="orientation" objtype="site" objname="imu" noise="0.001" />
    <framepos name="position" objtype="site" objname="imu" noise="0.001" />
    <gyro name="angular-velocity" site="imu" noise="0.005" cutoff="34.9" />
    <velocimeter name="linear-velocity" site="imu" noise="0.001" cutoff="30" />
    <accelerometer name="linear-acceleration" site="imu" noise="0.005" cutoff="157" />
    <magnetometer name="magnetometer" site="imu" /> -->

    <framequat     name='orientation' objtype='site' noise='0.001' objname='imu'/>
    <framepos     name='position' objtype='site' noise='0.001' objname='imu'/>
    <gyro          name='angular-velocity'    site='imu' noise='0.005' cutoff='34.9'/>
    <velocimeter   name='linear-velocity'     site='imu' noise='0.001' cutoff='30'/>
    <accelerometer name='linear-acceleration' site='imu' noise='0.005' cutoff='157'/>
    <magnetometer  name='magnetometer'        site='imu'/>
  </sensor>

</mujoco>
